<?xml version="1.0"?>

<robot name="my_robot">

<!--Colors-->

  <material name="green">
    <color rgba="0 0.7 0 1"/>
  </material>
  <material name="red">
    <color rgba="0.5 0 0 1"/>
  </material>
  <material name="blue">
    <color rgba="0 0 0.7 1"/>
  </material>


<!--LINKS-->

  <link name="base_link">
    <visual>
      <geometry>
        <box size="0.6 0.4 0.2" />
      </geometry> 
      <origin xyz="0.0 0.0 0.2" rpy="0.0 0.0 0.0"/>
      <material name="green"/>
    </visual>
  </link>  

  <link name="left_wheel">
    <visual>
      <geometry>
        <cylinder radius="0.1" length="0.05" />
      </geometry> 
      <origin xyz="0.0 0.0 0.0" rpy="0.0 0.0 0.0"/>
      <material name="red"/>
    </visual>
  </link>  

  <link name="right_wheel">
    <visual>
      <geometry>
        <cylinder radius="0.1" length="0.05" />
      </geometry> 
      <origin xyz="0.0 0.0 0.0" rpy="0.0 0.0 0.0"/>
      <material name="red"/>
    </visual>
  </link> 

  <link name="caster_wheel">
      <visual>
        <geometry>
          <sphere radius="0.05"/>
        </geometry> 
        <origin xyz="0.0 0.0 0.0" rpy="0.0 0.0 0.0"/>
        <material name="blue"/>
      </visual>
    </link>   

  <!--Joint-->
  <joint name="base_left_wheel_joint" type="continuous">
    <parent link="base_link" />
    <child link="left_wheel"/>
    <origin xyz="-0.15 -0.2025 0.1" rpy="1.570796 0 0"/>
    <axis xyz="0 0 1"/>
  </joint>

  <joint name="base_right_wheel_joint" type="continuous">
    <parent link="base_link" />
    <child link="right_wheel"/>
    <origin xyz="-0.15 0.2025 0.1" rpy="1.570796 0 0"/>
    <axis xyz="0 0 1"/>
  </joint>

  <joint name="base_caster_wheel_joint" type="fixed">
    <parent link="base_link" />
    <child link="caster_wheel"/>
    <origin xyz="0.15 0 0.05" rpy="0 0 0"/>
  </joint>

</robot>